<?xml version="1.0" encoding="utf-8"?>
<robot name="go2_one_leg">
  <link name="base_link">
    <inertial>
      <origin xyz="0.021112 0 -0.005366" rpy="0 0 0" />
      <mass value="6.921" />
      <inertia ixx="0.02448" ixy="0.00012166" ixz="0.0014849" iyy="0.098077" iyz="-3.12E-05" izz="0.107" />
    </inertial>
    <visual>
      <origin xyz="0 0 0" rpy="0 0 0" />
      <geometry>
        <mesh filename="package://one_leg_pinocchio_control/go2_description-humble/dae/base.dae" />
      </geometry>
      <material name="base_white">
        <color rgba="1 1 1 1" />
      </material>
    </visual>
    <collision>
      <origin xyz="0 0 0" rpy="0 0 0" />
      <geometry>
        <box size="0.3762 0.0935 0.114" />
      </geometry>
    </collision>
  </link>

  <link name="FL_hip">
    <inertial>
      <origin xyz="-0.0054 0.00194 -0.000105" rpy="0 0 0" />
      <mass value="0.678" />
      <inertia ixx="0.00048" ixy="-3.01E-06" ixz="1.11E-06" iyy="0.000884" iyz="-1.42E-06" izz="0.000596" />
    </inertial>
    <visual>
      <origin xyz="0 0 0" rpy="0 0 0" />
      <geometry>
        <mesh filename="package://one_leg_pinocchio_control/go2_description-humble/dae/hip.dae" />
      </geometry>
      <material name="hip_white">
        <color rgba="1 1 1 1" />
      </material>
    </visual>
    <collision>
      <origin xyz="0 0.08 0" rpy="1.5707963267948966 0 0" />
      <geometry>
        <cylinder length="0.04" radius="0.046" />
      </geometry>
    </collision>
  </link>

  <joint name="FL_hip_joint" type="revolute">
    <origin xyz="0.1934 0.0465 0" rpy="0 0 0" />
    <parent link="base_link" />
    <child link="FL_hip" />
    <axis xyz="1 0 0" />
    <limit lower="-1.0472" upper="1.0472" effort="23.7" velocity="30.1" />
  </joint>

  <link name="FL_thigh">
    <inertial>
      <origin xyz="-0.00374 -0.0223 -0.0327" rpy="0 0 0" />
      <mass value="1.152" />
      <inertia ixx="0.00584" ixy="8.72E-05" ixz="-0.000289" iyy="0.0058" iyz="0.000808" izz="0.00103" />
    </inertial>
    <visual>
      <origin xyz="0 0 0" rpy="0 0 0" />
      <geometry>
        <mesh filename="package://one_leg_pinocchio_control/go2_description-humble/dae/thigh.dae" />
      </geometry>
      <material name="thigh_white">
        <color rgba="1 1 1 1" />
      </material>
    </visual>
    <collision>
      <origin xyz="0 0 -0.1065" rpy="0 1.5707963267948966 0" />
      <geometry>
        <box size="0.213 0.0245 0.034" />
      </geometry>
    </collision>
  </link>

  <joint name="FL_thigh_joint" type="revolute">
    <origin xyz="0 0.0955 0" rpy="0 0 0" />
    <parent link="FL_hip" />
    <child link="FL_thigh" />
    <axis xyz="0 1 0" />
    <limit lower="-1.5708" upper="3.4907" effort="23.7" velocity="30.1" />
  </joint>

  <link name="FL_calf">
    <inertial>
      <origin xyz="0.00548 -0.000975 -0.115" rpy="0 0 0" />
      <mass value="0.154" />
      <inertia ixx="0.00108" ixy="3.4E-07" ixz="1.72E-05" iyy="0.0011" iyz="8.28E-06" izz="3.29E-05" />
    </inertial>
    <visual>
      <origin xyz="0 0 0" rpy="0 0 0" />
      <geometry>
        <mesh filename="package://one_leg_pinocchio_control/go2_description-humble/dae/calf.dae" />
      </geometry>
      <material name="calf_white">
        <color rgba="1 1 1 1" />
      </material>
    </visual>
    <collision>
      <origin xyz="0.008 0 -0.06" rpy="0 -0.21 0" />
      <geometry>
        <cylinder length="0.12" radius="0.012" />
      </geometry>
    </collision>
  </link>

  <joint name="FL_calf_joint" type="revolute">
    <origin xyz="0 0 -0.213" rpy="0 0 0" />
    <parent link="FL_thigh" />
    <child link="FL_calf" />
    <axis xyz="0 1 0" />
    <limit lower="-2.7227" upper="-0.83776" effort="45.43" velocity="15.70" />
  </joint>

  <link name="FL_foot">
    <inertial>
      <origin xyz="0 0 0" rpy="0 0 0" />
      <mass value="0.04" />
      <inertia ixx="9.6e-06" ixy="0" ixz="0" iyy="9.6e-06" iyz="0" izz="9.6e-06" />
    </inertial>
    <visual>
      <origin xyz="0 0 0" rpy="0 0 0" />
      <geometry>
        <mesh filename="package://one_leg_pinocchio_control/go2_description-humble/dae/foot.dae" />
      </geometry>
      <material name="foot_white">
        <color rgba="1 1 1 1" />
      </material>
    </visual>
    <collision>
      <origin xyz="-0.002 0 0" rpy="0 0 0" />
      <geometry>
        <sphere radius="0.022" />
      </geometry>
    </collision>
  </link>

  <joint name="FL_foot_joint" type="fixed">
    <origin xyz="0 0 -0.213" rpy="0 0 0" />
    <parent link="FL_calf" />
    <child link="FL_foot" />
  </joint>
</robot>
