<?xml version="1.0" encoding="utf-8"?>
<robot name="quad_mini">

  <link name="base">
    <visual>
      <origin xyz="0 0 0" rpy="0 0 0"/>
      <geometry>
        <box size="0.001 0.001 0.001"/>
      </geometry>
    </visual>
  </link>

  <joint name="floating_base" type="fixed">
    <origin rpy="0 0 3.14159265359" xyz="0 0 0"/>
    <parent link="base"/>
    <child link="trunk"/>
  </joint>

  <!-- BASE LINK -->
  <link name="trunk">
    <inertial>
      <origin xyz="-0.0069912 0.01165 -0.0071119" rpy="0 0 0"/>
      <mass value="4.1"/>
      <inertia ixx="0.014" ixy="0.0" ixz="0.0" iyy="0.058" iyz="0.0" izz="0.063"/>
    </inertial>
    <visual>
      <origin xyz="0 0.01165 0" rpy="0 0 0"/>
      <geometry>
        <mesh filename="meshes/base_link.obj"/>
      </geometry>
      <material name="body_white">
        <color rgba="0.985 0.985 0.97 1"/>
      </material>
    </visual>
    <collision>
      <origin xyz="0 0.01165 0" rpy="0 0 0"/>
      <geometry>
        <box size="0.40 0.16 0.11"/>
      </geometry>
    </collision>
  </link>

  <!-- RIGHT FRONT LEG -->
  <link name="RF_hip">
    <inertial>
      <origin xyz="0.03 0.05 0.0" rpy="0 0 0"/>
      <mass value="0.39"/>
      <inertia ixx="2.4616E-05" ixy="-8.0494E-07" ixz="2.0469E-07" iyy="2.4611E-05" iyz="1.6554E-07" izz="2.5415E-05"/>
    </inertial>
    <visual>
      <origin xyz="0 0 0" rpy="0 0 0"/>
      <geometry>
        <mesh filename="meshes/FR_HipX.obj"/>
      </geometry>
      <material name="body_white">
        <color rgba="0.985 0.985 0.97 1"/>
      </material>
    </visual>
    <collision>
      <origin xyz="0 0 0" rpy="0 0 0"/>
      <geometry>
        <mesh filename="meshes/FR_HipX.obj"/>
      </geometry>
    </collision>
  </link>

  <joint name="RF_HAA" type="revolute">
    <origin xyz="-0.15015 0.043877 0.009137" rpy="0 0 0"/>
    <parent link="trunk"/>
    <child link="RF_hip"/>
    <axis xyz="1 0 0"/>
    <limit lower="-0.436332" upper="0.436332" effort="12" velocity="11.52"/>
    <dynamics damping="0.05" friction="0.0"/>
  </joint>

  <link name="RF_thigh">
    <inertial>
      <origin xyz="0.0 0.040 -0.020" rpy="0 0 0"/>
      <mass value="0.725"/>
      <inertia ixx="4.7874E-05" ixy="-7.5529E-07" ixz="1.9319E-05" iyy="8.801E-05" iyz="-2.9232E-08" izz="7.0444E-05"/>
    </inertial>
    <visual>
      <origin xyz="0 0 0" rpy="0 0 0"/>
      <geometry>
        <mesh filename="meshes/FR_HipY.obj"/>
      </geometry>
      <material name="body_white">
        <color rgba="0.985 0.985 0.97 1"/>
      </material>
    </visual>
    <collision>
      <origin xyz="0 0 0" rpy="0 0 0"/>
      <geometry>
        <mesh filename="meshes/FR_HipY.obj"/>
      </geometry>
    </collision>
  </link>

  <joint name="RF_HFE" type="revolute">
    <origin xyz="0.033575 0.0327 0" rpy="0 0 0"/>
    <parent link="RF_hip"/>
    <child link="RF_thigh"/>
    <axis xyz="0 1 0"/>
    <limit lower="-0.1745" upper="3.316" effort="12" velocity="17.80"/>
    <dynamics damping="0.10" friction="0.01"/>
  </joint>

  <link name="RF_calf">
    <inertial>
      <origin xyz="-0.020 0.0 0.0" rpy="0 0 0"/>
      <mass value="0.106"/>
      <inertia ixx="4.8323E-06" ixy="-9.407E-09" ixz="5.6754E-07" iyy="1.731E-05" iyz="1.0071E-09" izz="1.675E-05"/>
    </inertial>
    <visual>
      <origin xyz="0 0 0" rpy="0 0 0"/>
      <geometry>
        <mesh filename="meshes/FR_Knee.obj"/>
      </geometry>
      <material name="knee_orange">
        <color rgba="0.97 0.50 0.08 1"/>
      </material>
    </visual>
    <collision>
      <origin xyz="0 0 0" rpy="0 0 0"/>
      <geometry>
        <mesh filename="meshes/FR_Knee.obj"/>
      </geometry>
    </collision>
  </link>

  <joint name="RF_KFE" type="revolute">
    <origin xyz="0.10286 0.06915 -0.061805" rpy="0 0 0"/>
    <parent link="RF_thigh"/>
    <child link="RF_calf"/>
    <axis xyz="0 1 0"/>
    <limit lower="-1.745529" upper="0.001" effort="12" velocity="17.80"/>
    <dynamics damping="0.12" friction="0.05"/>
  </joint>

  <link name="RF_FOOT">
    <inertial>
      <mass value="0.01"/>
      <origin xyz="0 0 0" rpy="0 0 0"/>
      <inertia ixx="1e-6" ixy="0" ixz="0" iyy="1e-6" iyz="0" izz="1e-6"/>
    </inertial>
    <visual>
      <origin xyz="0 0 0" rpy="0 0 0"/>
      <geometry>
        <sphere radius="0.022"/>
      </geometry>
      <material name="foot_blue">
        <color rgba="0.08 0.15 0.38 1"/>
      </material>
    </visual>
    <collision>
      <origin xyz="0 0 0" rpy="0 0 0"/>
      <geometry>
        <sphere radius="0.022"/>
      </geometry>
    </collision>
  </link>

  <joint name="RF_foot_fixed" type="fixed">
    <origin xyz="-0.135 0.005 0.0" rpy="0 0 0"/>
    <parent link="RF_calf"/>
    <child link="RF_FOOT"/>
  </joint>

  <!-- LEFT FRONT LEG -->
  <link name="LF_hip">
    <inertial>
      <origin xyz="0.03 -0.05 0.0" rpy="0 0 0"/>
      <mass value="0.39"/>
      <inertia ixx="2.4616E-05" ixy="8.0494E-07" ixz="-2.0469E-07" iyy="2.4611E-05" iyz="1.6554E-07" izz="2.5415E-05"/>
    </inertial>
    <visual>
      <origin xyz="0 0 0" rpy="0 0 0"/>
      <geometry>
        <mesh filename="meshes/FL_HipX.obj"/>
      </geometry>
      <material name="body_white">
        <color rgba="0.985 0.985 0.97 1"/>
      </material>
    </visual>
    <collision>
      <origin xyz="0 0 0" rpy="0 0 0"/>
      <geometry>
        <mesh filename="meshes/FL_HipX.obj"/>
      </geometry>
    </collision>
  </link>

  <joint name="LF_HAA" type="revolute">
    <origin xyz="-0.14915 -0.016123 0.009137" rpy="0 0 0"/>
    <parent link="trunk"/>
    <child link="LF_hip"/>
    <axis xyz="1 0 0"/>
    <limit lower="-0.436332" upper="0.436332" effort="12" velocity="11.52"/>
    <dynamics damping="0.05" friction="0.0"/>
  </joint>

  <link name="LF_thigh">
    <inertial>
      <origin xyz="0.0 -0.040 -0.020" rpy="0 0 0"/>
      <mass value="0.725"/>
      <inertia ixx="4.7766E-05" ixy="7.5543E-07" ixz="1.9208E-05" iyy="8.801E-05" iyz="-1.6086E-08" izz="7.0548E-05"/>
    </inertial>
    <visual>
      <origin xyz="0 0 0" rpy="0 0 0"/>
      <geometry>
        <mesh filename="meshes/FL_HipY.obj"/>
      </geometry>
      <material name="body_white">
        <color rgba="0.985 0.985 0.97 1"/>
      </material>
    </visual>
    <collision>
      <origin xyz="0 0 0" rpy="0 0 0"/>
      <geometry>
        <mesh filename="meshes/FL_HipY.obj"/>
      </geometry>
    </collision>
  </link>

  <joint name="LF_HFE" type="revolute">
    <origin xyz="0.032575 -0.033 0" rpy="0 0 0"/>
    <parent link="LF_hip"/>
    <child link="LF_thigh"/>
    <axis xyz="0 -1 0"/>
    <limit lower="-3.316" upper="0.1745" effort="12" velocity="17.80"/>
    <dynamics damping="0.10" friction="0.01"/>
  </joint>

  <link name="LF_calf">
    <inertial>
      <origin xyz="-0.020 0.0 0.0" rpy="0 0 0"/>
      <mass value="0.106"/>
      <inertia ixx="4.833E-06" ixy="-9.4065E-09" ixz="5.7428E-07" iyy="1.731E-05" iyz="1.0124E-09" izz="1.6749E-05"/>
    </inertial>
    <visual>
      <origin xyz="0 0 0" rpy="0 0 0"/>
      <geometry>
        <mesh filename="meshes/FL_Knee.obj"/>
      </geometry>
      <material name="knee_orange">
        <color rgba="0.97 0.50 0.08 1"/>
      </material>
    </visual>
    <collision>
      <origin xyz="0 0 0" rpy="0 0 0"/>
      <geometry>
        <mesh filename="meshes/FL_Knee.obj"/>
      </geometry>
    </collision>
  </link>

  <joint name="LF_KFE" type="revolute">
    <origin xyz="0.10303 -0.08105 -0.061521" rpy="0 0 0"/>
    <parent link="LF_thigh"/>
    <child link="LF_calf"/>
    <axis xyz="0 -1 0"/>
    <limit lower="-0.001" upper="1.745529" effort="12" velocity="17.80"/>
    <dynamics damping="0.12" friction="0.05"/>
  </joint>

  <link name="LF_FOOT">
    <inertial>
      <mass value="0.01"/>
      <origin xyz="0 0 0" rpy="0 0 0"/>
      <inertia ixx="1e-6" ixy="0" ixz="0" iyy="1e-6" iyz="0" izz="1e-6"/>
    </inertial>
    <visual>
      <origin xyz="0 0 0" rpy="0 0 0"/>
      <geometry>
        <sphere radius="0.022"/>
      </geometry>
      <material name="foot_blue">
        <color rgba="0.08 0.15 0.38 1"/>
      </material>
    </visual>
    <collision>
      <origin xyz="0 0 0" rpy="0 0 0"/>
      <geometry>
        <sphere radius="0.022"/>
      </geometry>
    </collision>
  </link>

  <joint name="LF_foot_fixed" type="fixed">
    <origin xyz="-0.135 0.005 0.0" rpy="0 0 0"/>
    <parent link="LF_calf"/>
    <child link="LF_FOOT"/>
  </joint>

  <!-- RIGHT HIND LEG -->
  <link name="RH_hip">
    <inertial>
      <origin xyz="-0.03 0.05 0.0" rpy="0 0 0"/>
      <mass value="0.39"/>
      <inertia ixx="2.4675E-05" ixy="1.1206E-06" ixz="-2.1657E-07" iyy="2.4611E-05" iyz="-1.4048E-07" izz="2.5355E-05"/>
    </inertial>
    <visual>
      <origin xyz="0 0 0" rpy="0 0 0"/>
      <geometry>
        <mesh filename="meshes/HR_HipX.obj"/>
      </geometry>
      <material name="body_white">
        <color rgba="0.985 0.985 0.97 1"/>
      </material>
    </visual>
    <collision>
      <origin xyz="0 0 0" rpy="0 0 0"/>
      <geometry>
        <mesh filename="meshes/HR_HipX.obj"/>
      </geometry>
    </collision>
  </link>

  <joint name="RH_HAA" type="revolute">
    <origin xyz="0.14685 0.043877 0.009137" rpy="0 0 0"/>
    <parent link="trunk"/>
    <child link="RH_hip"/>
    <axis xyz="-1 0 0"/>
    <limit lower="-0.436332" upper="0.436332" effort="12" velocity="11.52"/>
    <dynamics damping="0.05" friction="0.0"/>
  </joint>

  <link name="RH_thigh">
    <inertial>
      <origin xyz="0.0 0.040 -0.020" rpy="0 0 0"/>
      <mass value="0.725"/>
      <inertia ixx="4.9793E-05" ixy="-5.1435E-07" ixz="1.926E-05" iyy="9.2288E-05" iyz="-2.31E-07" izz="7.3197E-05"/>
    </inertial>
    <visual>
      <origin xyz="0 0 0" rpy="0 0 0"/>
      <geometry>
        <mesh filename="meshes/HR_HipY.obj"/>
      </geometry>
      <material name="body_white">
        <color rgba="0.985 0.985 0.97 1"/>
      </material>
    </visual>
    <collision>
      <origin xyz="0 0 0" rpy="0 0 0"/>
      <geometry>
        <mesh filename="meshes/HR_HipY.obj"/>
      </geometry>
    </collision>
  </link>

  <joint name="RH_HFE" type="revolute">
    <origin xyz="-0.032575 0.0329 0" rpy="0 0 0"/>
    <parent link="RH_hip"/>
    <child link="RH_thigh"/>
    <axis xyz="0 1 0"/>
    <limit lower="-0.1745" upper="3.316" effort="12" velocity="17.80"/>
    <dynamics damping="0.10" friction="0.01"/>
  </joint>

  <link name="RH_calf">
    <inertial>
      <origin xyz="-0.020 0.0 0.0" rpy="0 0 0"/>
      <mass value="0.106"/>
      <inertia ixx="4.8024E-06" ixy="-9.407E-09" ixz="5.6754E-07" iyy="1.7308E-05" iyz="1.007E-09" izz="1.672E-05"/>
    </inertial>
    <visual>
      <origin xyz="0 0 0" rpy="0 0 0"/>
      <geometry>
        <mesh filename="meshes/HR_Knee.obj"/>
      </geometry>
      <material name="knee_orange">
        <color rgba="0.97 0.50 0.08 1"/>
      </material>
    </visual>
    <collision>
      <origin xyz="0 0 0" rpy="0 0 0"/>
      <geometry>
        <mesh filename="meshes/HR_Knee.obj"/>
      </geometry>
    </collision>
  </link>

  <joint name="RH_KFE" type="revolute">
    <origin xyz="0.10286 0.06895 -0.061805" rpy="0 0 0"/>
    <parent link="RH_thigh"/>
    <child link="RH_calf"/>
    <axis xyz="0 1 0"/>
    <limit lower="-1.745529" upper="0.001" effort="12" velocity="17.80"/>
    <dynamics damping="0.12" friction="0.05"/>
  </joint>

  <link name="RH_FOOT">
    <inertial>
      <mass value="0.01"/>
      <origin xyz="0 0 0" rpy="0 0 0"/>
      <inertia ixx="1e-6" ixy="0" ixz="0" iyy="1e-6" iyz="0" izz="1e-6"/>
    </inertial>
    <visual>
      <origin xyz="0 0 0" rpy="0 0 0"/>
      <geometry>
        <sphere radius="0.022"/>
      </geometry>
      <material name="foot_blue">
        <color rgba="0.08 0.15 0.38 1"/>
      </material>
    </visual>
    <collision>
      <origin xyz="0 0 0" rpy="0 0 0"/>
      <geometry>
        <sphere radius="0.022"/>
      </geometry>
    </collision>
  </link>

  <joint name="RH_foot_fixed" type="fixed">
    <origin xyz="-0.135 0.005 0.0" rpy="0 0 0"/>
    <parent link="RH_calf"/>
    <child link="RH_FOOT"/>
  </joint>

  <!-- LEFT HIND LEG -->
  <link name="LH_hip">
    <inertial>
      <origin xyz="-0.03 -0.05 0.0" rpy="0 0 0"/>
      <mass value="0.39"/>
      <inertia ixx="2.4675E-05" ixy="-1.1206E-06" ixz="2.1657E-07" iyy="2.4611E-05" iyz="-1.4049E-07" izz="2.5355E-05"/>
    </inertial>
    <visual>
      <origin xyz="0 0 0" rpy="0 0 0"/>
      <geometry>
        <mesh filename="meshes/HL_HipX.obj"/>
      </geometry>
      <material name="body_white">
        <color rgba="0.985 0.985 0.97 1"/>
      </material>
    </visual>
    <collision>
      <origin xyz="0 0 0" rpy="0 0 0"/>
      <geometry>
        <mesh filename="meshes/HL_HipX.obj"/>
      </geometry>
    </collision>
  </link>

  <joint name="LH_HAA" type="revolute">
    <origin xyz="0.14785 -0.016123 0.009137" rpy="0 0 0"/>
    <parent link="trunk"/>
    <child link="LH_hip"/>
    <axis xyz="-1 0 0"/>
    <limit lower="-0.436332" upper="0.436332" effort="12" velocity="11.52"/>
    <dynamics damping="0.05" friction="0.0"/>
  </joint>

  <link name="LH_thigh">
    <inertial>
      <origin xyz="0.0 -0.040 -0.020" rpy="0 0 0"/>
      <mass value="0.725"/>
      <inertia ixx="4.7384E-05" ixy="5.1447E-07" ixz="1.9268E-05" iyy="8.9933E-05" iyz="-2.1784E-07" izz="7.1001E-05"/>
    </inertial>
    <visual>
      <origin xyz="0 0 0" rpy="0 0 0"/>
      <geometry>
        <mesh filename="meshes/HL_HipY.obj"/>
      </geometry>
      <material name="body_white">
        <color rgba="0.985 0.985 0.97 1"/>
      </material>
    </visual>
    <collision>
      <origin xyz="0 0 0" rpy="0 0 0"/>
      <geometry>
        <mesh filename="meshes/HL_HipY.obj"/>
      </geometry>
    </collision>
  </link>

  <joint name="LH_HFE" type="revolute">
    <origin xyz="-0.033575 -0.0329 0" rpy="0 0 0"/>
    <parent link="LH_hip"/>
    <child link="LH_thigh"/>
    <axis xyz="0 -1 0"/>
    <limit lower="-3.316" upper="0.1745" effort="12" velocity="17.80"/>
    <dynamics damping="0.10" friction="0.01"/>
  </joint>

  <link name="LH_calf">
    <inertial>
      <origin xyz="-0.020 0.0 0.0" rpy="0 0 0"/>
      <mass value="0.106"/>
      <inertia ixx="4.833E-06" ixy="-9.4071E-09" ixz="5.7428E-07" iyy="1.731E-05" iyz="1.013E-09" izz="1.6749E-05"/>
    </inertial>
    <visual>
      <origin xyz="0 0 0" rpy="0 0 0"/>
      <geometry>
        <mesh filename="meshes/HL_Knee.obj"/>
      </geometry>
      <material name="knee_orange">
        <color rgba="0.97 0.50 0.08 1"/>
      </material>
    </visual>
    <collision>
      <origin xyz="0 0 0" rpy="0 0 0"/>
      <geometry>
        <mesh filename="meshes/HL_Knee.obj"/>
      </geometry>
    </collision>
  </link>

  <joint name="LH_KFE" type="revolute">
    <origin xyz="0.10303 -0.08115 -0.061521" rpy="0 0 0"/>
    <parent link="LH_thigh"/>
    <child link="LH_calf"/>
    <axis xyz="0 -1 0"/>
    <limit lower="-0.001" upper="1.745529" effort="12" velocity="17.80"/>
    <dynamics damping="0.12" friction="0.05"/>
  </joint>

  <link name="LH_FOOT">
    <inertial>
      <mass value="0.01"/>
      <origin xyz="0 0 0" rpy="0 0 0"/>
      <inertia ixx="1e-6" ixy="0" ixz="0" iyy="1e-6" iyz="0" izz="1e-6"/>
    </inertial>
    <visual>
      <origin xyz="0 0 0" rpy="0 0 0"/>
      <geometry>
        <sphere radius="0.022"/>
      </geometry>
      <material name="foot_blue">
        <color rgba="0.08 0.15 0.38 1"/>
      </material>
    </visual>
    <collision>
      <origin xyz="0 0 0" rpy="0 0 0"/>
      <geometry>
        <sphere radius="0.022"/>
      </geometry>
    </collision>
  </link>

  <joint name="LH_foot_fixed" type="fixed">
    <origin xyz="-0.135 0.005 0.0" rpy="0 0 0"/>
    <parent link="LH_calf"/>
    <child link="LH_FOOT"/>
  </joint>


  <!-- IMU SENSOR -->
  <joint name="imu_joint" type="fixed">
    <parent link="trunk"/>
    <child link="imu_link"/>
    <origin rpy="0 0 0" xyz="0 0 0"/>
  </joint>

  <link name="imu_link">
    <inertial>
      <mass value="0.001"/>
      <origin rpy="0 0 0" xyz="0 0 0"/>
      <inertia ixx="0.0001" ixy="0" ixz="0" iyy="0.0001" iyz="0" izz="0.0001"/>
    </inertial>
    <visual>
      <origin rpy="0 0 0" xyz="0 0 0"/>
      <geometry>
        <box size="0.001 0.001 0.001"/>
      </geometry>
    </visual>
    <collision>
      <origin rpy="0 0 0" xyz="0 0 0"/>
      <geometry>
        <box size=".001 .001 .001"/>
      </geometry>
    </collision>
  </link>

  <gazebo>
    <plugin
      filename="libignition-gazebo-joint-state-publisher-system.so"
      name="ignition::gazebo::systems::JointStatePublisher">
      <topic>/joint_states_gz</topic>
    </plugin>
  </gazebo>

  <gazebo>
    <plugin
      filename="libignition-gazebo-odometry-publisher-system.so"
      name="ignition::gazebo::systems::OdometryPublisher">
      <odom_frame>odom</odom_frame>
      <robot_base_frame>base</robot_base_frame>
      <dimensions>3</dimensions>
      <odom_publish_frequency>250</odom_publish_frequency>
      <odom_topic>/odom</odom_topic>
    </plugin>
  </gazebo>

  <gazebo>
    <plugin
      filename="libignition-gazebo-imu-system.so"
      name="ignition::gazebo::systems::Imu"/>
  </gazebo>

  <gazebo>
    <plugin filename="libignition-gazebo-apply-joint-force-system.so" name="ignition::gazebo::systems::ApplyJointForce">
      <joint_name>LF_HAA</joint_name>
    </plugin>
  </gazebo>

  <gazebo>
    <plugin filename="libignition-gazebo-apply-joint-force-system.so" name="ignition::gazebo::systems::ApplyJointForce">
      <joint_name>LF_HFE</joint_name>
    </plugin>
  </gazebo>

  <gazebo>
    <plugin filename="libignition-gazebo-apply-joint-force-system.so" name="ignition::gazebo::systems::ApplyJointForce">
      <joint_name>LF_KFE</joint_name>
    </plugin>
  </gazebo>

  <gazebo>
    <plugin filename="libignition-gazebo-apply-joint-force-system.so" name="ignition::gazebo::systems::ApplyJointForce">
      <joint_name>LH_HAA</joint_name>
    </plugin>
  </gazebo>

  <gazebo>
    <plugin filename="libignition-gazebo-apply-joint-force-system.so" name="ignition::gazebo::systems::ApplyJointForce">
      <joint_name>LH_HFE</joint_name>
    </plugin>
  </gazebo>

  <gazebo>
    <plugin filename="libignition-gazebo-apply-joint-force-system.so" name="ignition::gazebo::systems::ApplyJointForce">
      <joint_name>LH_KFE</joint_name>
    </plugin>
  </gazebo>

  <gazebo>
    <plugin filename="libignition-gazebo-apply-joint-force-system.so" name="ignition::gazebo::systems::ApplyJointForce">
      <joint_name>RF_HAA</joint_name>
    </plugin>
  </gazebo>

  <gazebo>
    <plugin filename="libignition-gazebo-apply-joint-force-system.so" name="ignition::gazebo::systems::ApplyJointForce">
      <joint_name>RF_HFE</joint_name>
    </plugin>
  </gazebo>

  <gazebo>
    <plugin filename="libignition-gazebo-apply-joint-force-system.so" name="ignition::gazebo::systems::ApplyJointForce">
      <joint_name>RF_KFE</joint_name>
    </plugin>
  </gazebo>

  <gazebo>
    <plugin filename="libignition-gazebo-apply-joint-force-system.so" name="ignition::gazebo::systems::ApplyJointForce">
      <joint_name>RH_HAA</joint_name>
    </plugin>
  </gazebo>

  <gazebo>
    <plugin filename="libignition-gazebo-apply-joint-force-system.so" name="ignition::gazebo::systems::ApplyJointForce">
      <joint_name>RH_HFE</joint_name>
    </plugin>
  </gazebo>

  <gazebo>
    <plugin filename="libignition-gazebo-apply-joint-force-system.so" name="ignition::gazebo::systems::ApplyJointForce">
      <joint_name>RH_KFE</joint_name>
    </plugin>
  </gazebo>

  <gazebo reference="base">
    <sensor name="imu_sensor" type="imu">
      <always_on>1</always_on>
      <update_rate>250</update_rate>
      <topic>/imu/data</topic>
      <visualize>false</visualize>
      <imu>
        <angular_velocity>
          <x><noise type="gaussian"><mean>0.0</mean><stddev>0.0001</stddev></noise></x>
          <y><noise type="gaussian"><mean>0.0</mean><stddev>0.0001</stddev></noise></y>
          <z><noise type="gaussian"><mean>0.0</mean><stddev>0.0001</stddev></noise></z>
        </angular_velocity>
        <linear_acceleration>
          <x><noise type="gaussian"><mean>0.0</mean><stddev>0.0005</stddev></noise></x>
          <y><noise type="gaussian"><mean>0.0</mean><stddev>0.0005</stddev></noise></y>
          <z><noise type="gaussian"><mean>0.0</mean><stddev>0.0005</stddev></noise></z>
        </linear_acceleration>
      </imu>
    </sensor>
  </gazebo>

</robot>
